<?xml version="1.0" ?><!-- =================================================================================== --><!-- |    This document was autogenerated by xacro from /root/godot_ws/install/fastbot_description/share/fastbot_description/models/urdf/fastbot_multi_sim.xacro | --><!-- |    EDITING THIS FILE BY HAND IS NOT RECOMMENDED                                 | --><!-- =================================================================================== --><robot name="fastbot"><material name="grey"><color rgba="0.300 0.300 0.300 1.000"/></material><material name="black"><color rgba="0.000 0.000 0.000 1.000"/></material><material name="blue"><color rgba="0.000 0.000 1.000 1.000"/></material><!-- Link base_link --><link name="fastbot_1_base_link"><visual><origin rpy="0 0 0" xyz="0 0 0"/><geometry><mesh filename="package://fastbot_description/onshape/new_assets/fastbotchassis.dae"/></geometry></visual></link><!-- Link wheel_right --><link name="fastbot_1_wheel_right"><visual><origin rpy="0 0 0" xyz="0 0 0"/><geometry><mesh filename="package://fastbot_description/onshape/new_assets/wheeldae.dae"/></geometry></visual></link><!-- Joint from fastbot_motor to wheel_d65x25_v1 --><joint name="fastbot_1_right_wheel" type="continuous"><origin rpy="0 0 1.5708" xyz="-0.04091 -0.0479 0.014"/><parent link="fastbot_1_base_link"/><child link="fastbot_1_wheel_right"/><axis xyz="1 0 0"/></joint><!-- Link _wheel_left --><link name="fastbot_1_wheel_left"><visual><origin rpy="0 0 0" xyz="0 0 0"/><geometry><mesh filename="package://fastbot_description/onshape/new_assets/wheeldae.dae"/></geometry></visual></link><!-- Joint from fastbot_motor to wheel_d65x25_v1 --><joint name="fastbot_1_left_wheel" type="continuous"><origin rpy="0 0 -1.5708" xyz="-0.04091 0.0479 0.014"/><parent link="fastbot_1_base_link"/><child link="fastbot_1_wheel_left"/><axis xyz="-1 0 0"/></joint><!-- Link lslidar_n10 --><link name="fastbot_1_lidar"><visual><origin rpy="0 0 0" xyz="0 0 0"/><geometry><mesh filename="package://fastbot_description/onshape/new_assets/lydar.dae"/></geometry><material name="lslidar_n10_material"><color rgba="0.0980392 0.0980392 0.0980392 1.0"/></material></visual></link><!-- Joint from fastbot_chassis to lslidar_n10 --><joint name="fastbot_1_lidar" type="fixed"><origin rpy="0.0 0.0 0" xyz="0 0 0.108"/><parent link="fastbot_1_base_link"/><child link="fastbot_1_lidar"/><axis xyz="0 0 1"/></joint><!-- Link raspicam --><link name="fastbot_1_camera">
    </link><!-- Joint from fastbot_chassis to raspicam --><joint name="fastbot_1_camera" type="fixed"><origin rpy="0 0 0" xyz="0.087 0 0.087"/><parent link="fastbot_1_base_link"/><child link="fastbot_1_camera"/><axis xyz="0 0 1"/></joint></robot>
